<?xml version="1.0" encoding="utf-8" ?>
<!-- This URDF was automatically created by SolidWorks to URDF Exporter! Originally created by Stephen Brawner (brawner@gmail.com) 
     Commit Version: 1.6.0-4-g7f85cfe  Build Version: 1.6.7995.38578
     For more information, please see http://wiki.ros.org/sw_urdf_exporter -->
<robot name="jaka_s5">
    <link name="world"/>
    <joint name="fixed" type="fixed">
        <parent link="world"/>
        <child link="Link_0"/>
    </joint>
    <link name="Link_0">
        <inertial>
            <origin xyz="0.0028167 -0.00019454 0.019544" rpy="0 0 0" />
            <mass value="0.52663" />
            <inertia ixx="0.0006297" ixy="6.7091E-08" ixz="3.4682E-06" iyy="0.00095727" iyz="2.4476E-07" izz="0.0014514" />
        </inertial>
        <visual>
            <origin xyz="0 0 0" rpy="0 0 0" />
            <geometry>
                <mesh filename="package://hugmi_description/meshes/jaka_s5_meshes/Link_0.STL" />
            </geometry>
            <material name="">
                <color rgba="0.79216 0.81961 0.93333 1" />
            </material>
        </visual>
        <collision>
            <origin xyz="0 0 0" rpy="0 0 0" />
            <geometry>
                <mesh filename="package://hugmi_description/meshes/jaka_s5_meshes/Link_0.STL" />
            </geometry>
        </collision>
    </link>
    <link name="Link_1">
        <inertial>
            <origin xyz="-2.5186E-07 0.0033226 -0.001509" rpy="0 0 0" />
            <mass value="15.135" />
            <inertia ixx="0.044302" ixy="1.5349E-07" ixz="-6.1966E-07" iyy="0.043091" iyz="1.4326E-05" izz="0.030523" />
        </inertial>
        <visual>
            <origin xyz="0 0 0" rpy="0 0 0" />
            <geometry>
                <mesh filename="package://hugmi_description/meshes/jaka_s5_meshes/Link_1.STL" />
            </geometry>
            <material name="">
                <color rgba="0.84706 0.84706 0.84706 1" />
            </material>
        </visual>
        <collision>
            <origin xyz="0 0 0" rpy="0 0 0" />
            <geometry>
                <mesh filename="package://hugmi_description/meshes/jaka_s5_meshes/Link_1.STL" />
            </geometry>
        </collision>
    </link>
    <joint name="Joint1" type="revolute">
        <origin xyz="0 -0.00022535 0.12015" rpy="0 0 0" />
        <parent link="Link_0" />
        <child link="Link_1" />
        <axis xyz="0 0 -1" />
        <limit lower="-6.28" upper="6.28" effort="2000" velocity="1.57" />
    </joint>
    <link name="Link_2">
        <inertial>
            <origin xyz="0.215 6.4325E-09 -0.14315" rpy="0 0 0" />
            <mass value="45.847" />
            <inertia ixx="0.10377" ixy="-1.3562E-06" ixz="2.544E-07" iyy="1.5964" iyz="2.1509E-08" izz="1.5689" />
        </inertial>
        <visual>
            <origin xyz="0 0 0" rpy="0 0 0" />
            <geometry>
                <mesh filename="package://hugmi_description/meshes/jaka_s5_meshes/Link_2.STL" />
            </geometry>
            <material name="">
                <color rgba="0.84706 0.84706 0.84706 1" />
            </material>
        </visual>
        <collision>
            <origin xyz="0 0 0" rpy="0 0 0" />
            <geometry>
                <mesh filename="package://hugmi_description/meshes/jaka_s5_meshes/Link_2.STL" />
            </geometry>
        </collision>
    </link>
    <joint name="Joint2" type="revolute">
        <origin xyz="0 0 0" rpy="1.5708 0 0" />
        <parent link="Link_1" />
        <child link="Link_2" />
        <axis xyz="0 0 1" />
        <limit lower="-1.48" upper="4.62" effort="5000" velocity="1.57" />
    </joint>
    <link name="Link_3">
        <inertial>
            <origin xyz="0.19077 -1.059E-08 -0.010626" rpy="0 0 0" />
            <mass value="18.05" />
            <inertia ixx="0.02199" ixy="-3.4623E-06" ixz="-0.022409" iyy="0.41563" iyz="9.5677E-09" izz="0.41008" />
        </inertial>
        <visual>
            <origin xyz="0 0 0" rpy="0 0 0" />
            <geometry>
                <mesh filename="package://hugmi_description/meshes/jaka_s5_meshes/Link_3.STL" />
            </geometry>
            <material name="">
                <color rgba="0.84706 0.84706 0.84706 1" />
            </material>
        </visual>
        <collision>
            <origin xyz="0 0 0" rpy="0 0 0" />
            <geometry>
                <mesh filename="package://hugmi_description/meshes/jaka_s5_meshes/Link_3.STL" />
            </geometry>
        </collision>
    </link>
    <joint name="Joint3" type="revolute">
        <origin xyz="0.43 0 0" rpy="0 0 0" />
        <parent link="Link_2" />
        <child link="Link_3" />
        <axis xyz="0 0 1" />
        <limit lower="-3.05" upper="3.05" effort="5000" velocity="1.57" />
    </joint>
    <link name="Link_4">
        <inertial>
            <origin xyz="-2.1463E-06 -0.0059512 0.0026789" rpy="0 0 0" />
            <mass value="5.5377" />
            <inertia ixx="0.0092004" ixy="1.17E-07" ixz="-1.3683E-08" iyy="0.0052083" iyz="-8.5741E-05" izz="0.0089125" />
        </inertial>
        <visual>
            <origin xyz="0 0 0" rpy="0 0 0" />
            <geometry>
                <mesh filename="package://hugmi_description/meshes/jaka_s5_meshes/Link_4.STL" />
            </geometry>
            <material name="">
                <color rgba="0.84706 0.84706 0.84706 1" />
            </material>
        </visual>
        <collision>
            <origin xyz="0 0 0" rpy="0 0 0" />
            <geometry>
                <mesh filename="package://hugmi_description/meshes/jaka_s5_meshes/Link_4.STL" />
            </geometry>
        </collision>
    </link>
    <joint name="Joint4" type="revolute">
        <origin xyz="0.3685 0 -0.114" rpy="0 0 0" />
        <parent link="Link_3" />
        <child link="Link_4" />
        <axis xyz="0 0 1" />
        <limit lower="-1.48" upper="4.62" effort="2000" velocity="1.57" />
    </joint>
    <link name="Link_5">
        <inertial>
            <origin xyz="-2.0304E-06 -0.0028889 -0.0023424" rpy="0 0 0" />
            <mass value="6.3339" />
            <inertia ixx="0.012993" ixy="-1.0764E-07" ixz="5.8559E-09" iyy="0.0058454" iyz="4.5426E-05" izz="0.0127" />
        </inertial>
        <visual>
            <origin xyz="0 0 0" rpy="0 0 0" />
            <geometry>
                <mesh filename="package://hugmi_description/meshes/jaka_s5_meshes/Link_5.STL" />
            </geometry>
            <material name="">
                <color rgba="0.84706 0.84706 0.84706 1" />
            </material>
        </visual>
        <collision>
            <origin xyz="0 0 0" rpy="0 0 0" />
            <geometry>
                <mesh filename="package://hugmi_description/meshes/jaka_s5_meshes/Link_5.STL" />
            </geometry>
        </collision>
    </link>
    <joint name="Joint5" type="revolute">
        <origin xyz="0 -0.1135 0" rpy="1.5708 0 0" />
        <parent link="Link_4" />
        <child link="Link_5" />
        <axis xyz="0 0 1" />
        <limit lower="-6.28" upper="6.28" effort="3000" velocity="1.57" />
    </joint>
    <link name="Link_6">
        <inertial>
            <origin xyz="-0.00024331 0.00030548 -0.026411" rpy="0 0 0" />
            <mass value="0.23261" />
            <inertia ixx="0.0001349" ixy="-6.8669E-08" ixz="-9.4918E-08" iyy="0.00013541" iyz="2.8456E-07" izz="0.00018606" />
        </inertial>
        <visual>
            <origin xyz="0 0 0" rpy="0 0 0" />
            <geometry>
                <mesh filename="package://hugmi_description/meshes/jaka_s5_meshes/Link_6.STL" />
            </geometry>
            <material name="">
                <color rgba="0.79216 0.81961 0.93333 1" />
            </material>
        </visual>
        <collision>
            <origin xyz="0 0 0" rpy="0 0 0" />
            <geometry>
                <mesh filename="package://hugmi_description/meshes/jaka_s5_meshes/Link_6.STL" />
            </geometry>
        </collision>
    </link>
    <joint name="Joint6" type="revolute">
        <origin xyz="0.00026137 0.1175 0.00025782" rpy="-1.5708 0 0" />
        <parent link="Link_5" />
        <child link="Link_6" />
        <axis xyz="0 0 1" />
        <limit lower="-6.28" upper="6.28" effort="1000" velocity="1.57" />
    </joint>
    <transmission name="trans_Joint1">
        <type>transmission_interface/SimpleTransmission</type>
        <joint name="Joint1">
            <hardwareInterface>hardware_interface/PositionJointInterface</hardwareInterface>
        </joint>
        <actuator name="Joint1_motor">
            <hardwareInterface>hardware_interface/PositionJointInterface</hardwareInterface>
            <mechanicalReduction>1</mechanicalReduction>
        </actuator>
    </transmission>
    <transmission name="trans_Joint2">
        <type>transmission_interface/SimpleTransmission</type>
        <joint name="Joint2">
            <hardwareInterface>hardware_interface/PositionJointInterface</hardwareInterface>
        </joint>
        <actuator name="Joint2_motor">
            <hardwareInterface>hardware_interface/PositionJointInterface</hardwareInterface>
            <mechanicalReduction>1</mechanicalReduction>
        </actuator>
    </transmission>
    <transmission name="trans_Joint3">
        <type>transmission_interface/SimpleTransmission</type>
        <joint name="Joint3">
            <hardwareInterface>hardware_interface/PositionJointInterface</hardwareInterface>
        </joint>
        <actuator name="Joint3_motor">
            <hardwareInterface>hardware_interface/PositionJointInterface</hardwareInterface>
            <mechanicalReduction>1</mechanicalReduction>
        </actuator>
    </transmission>
    <transmission name="trans_Joint4">
        <type>transmission_interface/SimpleTransmission</type>
        <joint name="Joint4">
            <hardwareInterface>hardware_interface/PositionJointInterface</hardwareInterface>
        </joint>
        <actuator name="Joint4_motor">
            <hardwareInterface>hardware_interface/PositionJointInterface</hardwareInterface>
            <mechanicalReduction>1</mechanicalReduction>
        </actuator>
    </transmission>
    <transmission name="trans_Joint5">
        <type>transmission_interface/SimpleTransmission</type>
        <joint name="Joint5">
            <hardwareInterface>hardware_interface/PositionJointInterface</hardwareInterface>
        </joint>
        <actuator name="Joint5_motor">
            <hardwareInterface>hardware_interface/PositionJointInterface</hardwareInterface>
            <mechanicalReduction>1</mechanicalReduction>
        </actuator>
    </transmission>
    <transmission name="trans_Joint6">
        <type>transmission_interface/SimpleTransmission</type>
        <joint name="Joint6">
            <hardwareInterface>hardware_interface/PositionJointInterface</hardwareInterface>
        </joint>
        <actuator name="Joint6_motor">
            <hardwareInterface>hardware_interface/PositionJointInterface</hardwareInterface>
            <mechanicalReduction>1</mechanicalReduction>
        </actuator>
    </transmission>
    <gazebo>
        <plugin name="gazebo_ros_control" filename="libgazebo_ros_control.so">
            <robotNamespace>/</robotNamespace>
        </plugin>
    </gazebo>
</robot>

