<?xml version="1.0" encoding="utf-8" ?>
<robot xmlns:xacro="http://www.ros.org/wiki/xacro">

    <xacro:macro name="jaka_s5_arm" params="name prefix parent *origin initial_positions_file"> 

        <!-- ros2_control -->
        <xacro:include filename="$(find hugmi_description)/urdf/jaka_s5_arm.ros2_control.xacro" />
        <xacro:jaka_s5_arm_ros2_control name="${name}" initial_positions_file="${initial_positions_file}" prefix="${prefix}"/>
        
        <!-- base_joint fixes base_link to the environment--> 
        <joint name="${prefix}base_joint" type="fixed">
            <xacro:insert_block name="origin" />
            <parent link="${parent}"/>
            <child link="${prefix}link_0"/>
        </joint>
        <link name="${prefix}link_0">
            <inertial>
                <origin xyz="0.0028167 -0.00019454 0.019544" rpy="0 0 0" />
                <mass value="0.52663" />
                <inertia ixx="0.0006297" ixy="6.7091E-08" ixz="3.4682E-06" iyy="0.00095727" iyz="2.4476E-07" izz="0.0014514" />
            </inertial>
            <visual>
                <origin xyz="0 0 0" rpy="0 0 0" />
                <geometry>
                    <mesh filename="package://hugmi_description/meshes/jaka_s5_meshes/link_0.STL" />
                </geometry>
                <material name="">
                    <color rgba="0.79216 0.81961 0.93333 1" />
                </material>
            </visual>
            <collision>
                <origin xyz="0 0 0" rpy="0 0 0" />
                <geometry>
                    <mesh filename="package://hugmi_description/meshes/jaka_s5_meshes/link_0.STL" />
                </geometry>
            </collision>
        </link>
        <link name="${prefix}link_1">
            <inertial>
                <origin xyz="-2.5186E-07 0.0033226 -0.001509" rpy="0 0 0" />
                <mass value="15.135" />
                <inertia ixx="0.044302" ixy="1.5349E-07" ixz="-6.1966E-07" iyy="0.043091" iyz="1.4326E-05" izz="0.030523" />
            </inertial>
            <visual>
                <origin xyz="0 0 0" rpy="0 0 0" />
                <geometry>
                    <mesh filename="package://hugmi_description/meshes/jaka_s5_meshes/link_1.STL" />
                </geometry>
                <material name="">
                    <color rgba="0.84706 0.84706 0.84706 1" />
                </material>
            </visual>
            <collision>
                <origin xyz="0 0 0" rpy="0 0 0" />
                <geometry>
                    <mesh filename="package://hugmi_description/meshes/jaka_s5_meshes/link_1.STL" />
                </geometry>
            </collision>
        </link>
        <joint name="${prefix}joint1" type="revolute">
            <origin xyz="0 -0.00022535 0.12015" rpy="0 0 0" />
            <parent link="${prefix}link_0" />
            <child link="${prefix}link_1" />
            <axis xyz="0 0 -1" />
            <limit lower="-6.28" upper="6.28" effort="2000" velocity="1.57" />
        </joint>
        <link name="${prefix}link_2">
            <inertial>
                <origin xyz="0.215 6.4325E-09 -0.14315" rpy="0 0 0" />
                <mass value="45.847" />
                <inertia ixx="0.10377" ixy="-1.3562E-06" ixz="2.544E-07" iyy="1.5964" iyz="2.1509E-08" izz="1.5689" />
            </inertial>
            <visual>
                <origin xyz="0 0 0" rpy="0 0 0" />
                <geometry>
                    <mesh filename="package://hugmi_description/meshes/jaka_s5_meshes/link_2.STL" />
                </geometry>
                <material name="">
                    <color rgba="0.84706 0.84706 0.84706 1" />
                </material>
            </visual>
            <collision>
                <origin xyz="0 0 0" rpy="0 0 0" />
                <geometry>
                    <mesh filename="package://hugmi_description/meshes/jaka_s5_meshes/link_2.STL" />
                </geometry>
            </collision>
        </link>
        <joint name="${prefix}joint2" type="revolute">
            <origin xyz="0 0 0" rpy="1.5708 0 0" />
            <parent link="${prefix}link_1" />
            <child link="${prefix}link_2" />
            <axis xyz="0 0 1" />
            <limit lower="-1.48" upper="4.62" effort="5000" velocity="1.57" />
        </joint>
        <link name="${prefix}link_3">
            <inertial>
                <origin xyz="0.19077 -1.059E-08 -0.010626" rpy="0 0 0" />
                <mass value="18.05" />
                <inertia ixx="0.02199" ixy="-3.4623E-06" ixz="-0.022409" iyy="0.41563" iyz="9.5677E-09" izz="0.41008" />
            </inertial>
            <visual>
                <origin xyz="0 0 0" rpy="0 0 0" />
                <geometry>
                    <mesh filename="package://hugmi_description/meshes/jaka_s5_meshes/link_3.STL" />
                </geometry>
                <material name="">
                    <color rgba="0.84706 0.84706 0.84706 1" />
                </material>
            </visual>
            <collision>
                <origin xyz="0 0 0" rpy="0 0 0" />
                <geometry>
                    <mesh filename="package://hugmi_description/meshes/jaka_s5_meshes/link_3.STL" />
                </geometry>
            </collision>
        </link>
        <joint name="${prefix}joint3" type="revolute">
            <origin xyz="0.43 0 0" rpy="0 0 0" />
            <parent link="${prefix}link_2" />
            <child link="${prefix}link_3" />
            <axis xyz="0 0 1" />
            <limit lower="-3.05" upper="3.05" effort="5000" velocity="1.57" />
        </joint>
        <link name="${prefix}link_4">
            <inertial>
                <origin xyz="-2.1463E-06 -0.0059512 0.0026789" rpy="0 0 0" />
                <mass value="5.5377" />
                <inertia ixx="0.0092004" ixy="1.17E-07" ixz="-1.3683E-08" iyy="0.0052083" iyz="-8.5741E-05" izz="0.0089125" />
            </inertial>
            <visual>
                <origin xyz="0 0 0" rpy="0 0 0" />
                <geometry>
                    <mesh filename="package://hugmi_description/meshes/jaka_s5_meshes/link_4.STL" />
                </geometry>
                <material name="">
                    <color rgba="0.84706 0.84706 0.84706 1" />
                </material>
            </visual>
            <collision>
                <origin xyz="0 0 0" rpy="0 0 0" />
                <geometry>
                    <mesh filename="package://hugmi_description/meshes/jaka_s5_meshes/link_4.STL" />
                </geometry>
            </collision>
        </link>
        <joint name="${prefix}joint4" type="revolute">
            <origin xyz="0.3685 0 -0.114" rpy="0 0 0" />
            <parent link="${prefix}link_3" />
            <child link="${prefix}link_4" />
            <axis xyz="0 0 1" />
            <limit lower="-1.48" upper="4.62" effort="2000" velocity="1.57" />
        </joint>
        <link name="${prefix}link_5">
            <inertial>
                <origin xyz="-2.0304E-06 -0.0028889 -0.0023424" rpy="0 0 0" />
                <mass value="6.3339" />
                <inertia ixx="0.012993" ixy="-1.0764E-07" ixz="5.8559E-09" iyy="0.0058454" iyz="4.5426E-05" izz="0.0127" />
            </inertial>
            <visual>
                <origin xyz="0 0 0" rpy="0 0 0" />
                <geometry>
                    <mesh filename="package://hugmi_description/meshes/jaka_s5_meshes/link_5.STL" />
                </geometry>
                <material name="">
                    <color rgba="0.84706 0.84706 0.84706 1" />
                </material>
            </visual>
            <collision>
                <origin xyz="0 0 0" rpy="0 0 0" />
                <geometry>
                    <mesh filename="package://hugmi_description/meshes/jaka_s5_meshes/link_5.STL" />
                </geometry>
            </collision>
        </link>
        <joint name="${prefix}joint5" type="revolute">
            <origin xyz="0 -0.1135 0" rpy="1.5708 0 0" />
            <parent link="${prefix}link_4" />
            <child link="${prefix}link_5" />
            <axis xyz="0 0 1" />
            <limit lower="-6.28" upper="6.28" effort="3000" velocity="1.57" />
        </joint>
        <link name="${prefix}link_6">
            <inertial>
                <origin xyz="-0.00024331 0.00030548 -0.026411" rpy="0 0 0" />
                <mass value="0.23261" />
                <inertia ixx="0.0001349" ixy="-6.8669E-08" ixz="-9.4918E-08" iyy="0.00013541" iyz="2.8456E-07" izz="0.00018606" />
            </inertial>
            <visual>
                <origin xyz="0 0 0" rpy="0 0 0" />
                <geometry>
                    <mesh filename="package://hugmi_description/meshes/jaka_s5_meshes/link_6.STL" />
                </geometry>
                <material name="">
                    <color rgba="0.79216 0.81961 0.93333 1" />
                </material>
            </visual>
            <collision>
                <origin xyz="0 0 0" rpy="0 0 0" />
                <geometry>
                    <mesh filename="package://hugmi_description/meshes/jaka_s5_meshes/link_6.STL" />
                </geometry>
            </collision>
        </link>
        <joint name="${prefix}joint6" type="revolute">
            <origin xyz="0.00026137 0.1175 0.00025782" rpy="-1.5708 0 0" />
            <parent link="${prefix}link_5" />
            <child link="${prefix}link_6" />
            <axis xyz="0 0 1" />
            <limit lower="-6.28" upper="6.28" effort="1000" velocity="1.57" />
        </joint>
        <transmission name="${prefix}trans_joint1">
            <type>transmission_interface/SimpleTransmission</type>
            <joint name="${prefix}joint1">
                <hardwareInterface>hardware_interface/PositionJointInterface</hardwareInterface>
            </joint>
            <actuator name="${prefix}joint1_motor">
                <hardwareInterface>hardware_interface/PositionJointInterface</hardwareInterface>
                <mechanicalReduction>1</mechanicalReduction>
            </actuator>
        </transmission>
        <transmission name="${prefix}trans_joint2">
            <type>transmission_interface/SimpleTransmission</type>
            <joint name="${prefix}joint2">
                <hardwareInterface>hardware_interface/PositionJointInterface</hardwareInterface>
            </joint>
            <actuator name="${prefix}joint2_motor">
                <hardwareInterface>hardware_interface/PositionJointInterface</hardwareInterface>
                <mechanicalReduction>1</mechanicalReduction>
            </actuator>
        </transmission>
        <transmission name="${prefix}trans_joint3">
            <type>transmission_interface/SimpleTransmission</type>
            <joint name="${prefix}joint3">
                <hardwareInterface>hardware_interface/PositionJointInterface</hardwareInterface>
            </joint>
            <actuator name="${prefix}joint3_motor">
                <hardwareInterface>hardware_interface/PositionJointInterface</hardwareInterface>
                <mechanicalReduction>1</mechanicalReduction>
            </actuator>
        </transmission>
        <transmission name="${prefix}trans_joint4">
            <type>transmission_interface/SimpleTransmission</type>
            <joint name="${prefix}joint4">
                <hardwareInterface>hardware_interface/PositionJointInterface</hardwareInterface>
            </joint>
            <actuator name="${prefix}joint4_motor">
                <hardwareInterface>hardware_interface/PositionJointInterface</hardwareInterface>
                <mechanicalReduction>1</mechanicalReduction>
            </actuator>
        </transmission>
        <transmission name="${prefix}trans_joint5">
            <type>transmission_interface/SimpleTransmission</type>
            <joint name="${prefix}joint5">
                <hardwareInterface>hardware_interface/PositionJointInterface</hardwareInterface>
            </joint>
            <actuator name="${prefix}joint5_motor">
                <hardwareInterface>hardware_interface/PositionJointInterface</hardwareInterface>
                <mechanicalReduction>1</mechanicalReduction>
            </actuator>
        </transmission>
        <transmission name="${prefix}trans_joint6">
            <type>transmission_interface/SimpleTransmission</type>
            <joint name="${prefix}joint6">
                <hardwareInterface>hardware_interface/PositionJointInterface</hardwareInterface>
            </joint>
            <actuator name="${prefix}joint6_motor">
                <hardwareInterface>hardware_interface/PositionJointInterface</hardwareInterface>
                <mechanicalReduction>1</mechanicalReduction>
            </actuator>
        </transmission>
        <gazebo>
            <plugin name="gazebo_ros_control" filename="libgazebo_ros_control.so">
                <robotNamespace>/</robotNamespace>
            </plugin>
        </gazebo>
    </xacro:macro>
</robot>

